[2025-10-10T03:27:52.163+0000] {local_task_job_runner.py:120} INFO - ::group::Pre task execution logs
[2025-10-10T03:27:52.188+0000] {taskinstance.py:2076} INFO - Dependencies all met for dep_context=non-requeueable deps ti=<TaskInstance: update_db.staging_table manual__2025-10-10T03:22:48.381861+00:00 [queued]>
[2025-10-10T03:27:52.198+0000] {taskinstance.py:2076} INFO - Dependencies all met for dep_context=requeueable deps ti=<TaskInstance: update_db.staging_table manual__2025-10-10T03:22:48.381861+00:00 [queued]>
[2025-10-10T03:27:52.199+0000] {taskinstance.py:2306} INFO - Starting attempt 2 of 2
[2025-10-10T03:27:52.216+0000] {taskinstance.py:2330} INFO - Executing <Task(_PythonDecoratedOperator): staging_table> on 2025-10-10 03:22:48.381861+00:00
[2025-10-10T03:27:52.221+0000] {standard_task_runner.py:63} INFO - Started process 207 to run task
[2025-10-10T03:27:52.225+0000] {standard_task_runner.py:90} INFO - Running: ['airflow', 'tasks', 'run', 'update_db', 'staging_table', 'manual__2025-10-10T03:22:48.381861+00:00', '--job-id', '21', '--raw', '--subdir', 'DAGS_FOLDER/main.py', '--cfg-path', '/tmp/tmpina9w7ni']
[2025-10-10T03:27:52.227+0000] {standard_task_runner.py:91} INFO - Job 21: Subtask staging_table
[2025-10-10T03:27:52.302+0000] {task_command.py:426} INFO - Running <TaskInstance: update_db.staging_table manual__2025-10-10T03:22:48.381861+00:00 [running]> on host 56a6dee4e1d8
[2025-10-10T03:27:52.392+0000] {taskinstance.py:2648} INFO - Exporting env vars: AIRFLOW_CTX_DAG_OWNER='data_engineer' AIRFLOW_CTX_DAG_ID='update_db' AIRFLOW_CTX_TASK_ID='staging_table' AIRFLOW_CTX_EXECUTION_DATE='2025-10-10T03:22:48.381861+00:00' AIRFLOW_CTX_TRY_NUMBER='2' AIRFLOW_CTX_DAG_RUN_ID='manual__2025-10-10T03:22:48.381861+00:00'
[2025-10-10T03:27:52.393+0000] {taskinstance.py:430} INFO - ::endgroup::
[2025-10-10T03:27:52.404+0000] {base.py:84} INFO - Using connection ID 'postgres_db_yt_elt' for task execution.
[2025-10-10T03:27:52.409+0000] {data_loading.py:13} INFO - Processing file: YT_data_2025-10-10
[2025-10-10T03:27:52.410+0000] {data_loading.py:19} ERROR - File not found:./data/YT_data_2025-10-10.json
[2025-10-10T03:27:52.411+0000] {dwh.py:59} ERROR - An error occurred during the update of staging table: [Errno 2] No such file or directory: './data/YT_data_2025-10-10.json'
[2025-10-10T03:27:52.412+0000] {taskinstance.py:441} INFO - ::group::Post task execution logs
[2025-10-10T03:27:52.413+0000] {taskinstance.py:2905} ERROR - Task failed with exception
Traceback (most recent call last):
  File "/home/airflow/.local/lib/python3.10/site-packages/airflow/models/taskinstance.py", line 465, in _execute_task
    result = _execute_callable(context=context, **execute_callable_kwargs)
  File "/home/airflow/.local/lib/python3.10/site-packages/airflow/models/taskinstance.py", line 432, in _execute_callable
    return execute_callable(context=context, **execute_callable_kwargs)
  File "/home/airflow/.local/lib/python3.10/site-packages/airflow/models/baseoperator.py", line 401, in wrapper
    return func(self, *args, **kwargs)
  File "/home/airflow/.local/lib/python3.10/site-packages/airflow/decorators/base.py", line 265, in execute
    return_value = super().execute(context)
  File "/home/airflow/.local/lib/python3.10/site-packages/airflow/models/baseoperator.py", line 401, in wrapper
    return func(self, *args, **kwargs)
  File "/home/airflow/.local/lib/python3.10/site-packages/airflow/operators/python.py", line 235, in execute
    return_value = self.execute_callable()
  File "/home/airflow/.local/lib/python3.10/site-packages/airflow/operators/python.py", line 252, in execute_callable
    return self.python_callable(*self.op_args, **self.op_kwargs)
  File "/opt/airflow/dags/datawarehouse/dwh.py", line 60, in staging_table
    raise e
  File "/opt/airflow/dags/datawarehouse/dwh.py", line 31, in staging_table
    YT_data = load_data()
  File "/opt/airflow/dags/datawarehouse/data_loading.py", line 15, in load_data
    with open(file_path, "r", encoding="utf-8") as raw_data:
FileNotFoundError: [Errno 2] No such file or directory: './data/YT_data_2025-10-10.json'
[2025-10-10T03:27:52.429+0000] {taskinstance.py:1206} INFO - Marking task as FAILED. dag_id=update_db, task_id=staging_table, run_id=manual__2025-10-10T03:22:48.381861+00:00, execution_date=20251010T032248, start_date=20251010T032752, end_date=20251010T032752
[2025-10-10T03:27:52.444+0000] {standard_task_runner.py:110} ERROR - Failed to execute job 21 for task staging_table ([Errno 2] No such file or directory: './data/YT_data_2025-10-10.json'; 207)
[2025-10-10T03:27:52.480+0000] {local_task_job_runner.py:240} INFO - Task exited with return code 1
[2025-10-10T03:27:52.506+0000] {taskinstance.py:3503} INFO - 0 downstream tasks scheduled from follow-on schedule check
[2025-10-10T03:27:52.512+0000] {local_task_job_runner.py:222} INFO - ::endgroup::
